2021-11-20 17:08:42,050 - apscheduler.scheduler - INFO - Scheduler started
2021-11-20 17:13:03,257 - telegram.ext.updater - ERROR - Error while getting Updates: Conflict: terminated by other getUpdates request; make sure that only one bot instance is running
2021-11-20 17:13:03,257 - codec.tg - ERROR - Exception while handling an update:
Traceback (most recent call last):
  File "/Library/Frameworks/Python.framework/Versions/3.8/lib/python3.8/site-packages/telegram/ext/updater.py", line 646, in _network_loop_retry
    if not action_cb():
  File "/Library/Frameworks/Python.framework/Versions/3.8/lib/python3.8/site-packages/telegram/ext/updater.py", line 597, in polling_action_cb
    updates = self.bot.get_updates(
  File "/Library/Frameworks/Python.framework/Versions/3.8/lib/python3.8/site-packages/telegram/ext/extbot.py", line 222, in get_updates
    updates = super().get_updates(
  File "/Library/Frameworks/Python.framework/Versions/3.8/lib/python3.8/site-packages/telegram/bot.py", line 130, in decorator
    result = func(*args, **kwargs)
  File "/Library/Frameworks/Python.framework/Versions/3.8/lib/python3.8/site-packages/telegram/bot.py", line 2861, in get_updates
    self._post(
  File "/Library/Frameworks/Python.framework/Versions/3.8/lib/python3.8/site-packages/telegram/bot.py", line 295, in _post
    return self.request.post(
  File "/Library/Frameworks/Python.framework/Versions/3.8/lib/python3.8/site-packages/telegram/utils/request.py", line 361, in post
    result = self._request_wrapper(
  File "/Library/Frameworks/Python.framework/Versions/3.8/lib/python3.8/site-packages/telegram/utils/request.py", line 283, in _request_wrapper
    raise Conflict(message)
telegram.error.Conflict: Conflict: terminated by other getUpdates request; make sure that only one bot instance is running
2021-11-20 17:13:03,265 - telegram.ext.dispatcher - ERROR - An uncaught error was raised while handling the error.
Traceback (most recent call last):
  File "/Library/Frameworks/Python.framework/Versions/3.8/lib/python3.8/site-packages/telegram/ext/dispatcher.py", line 536, in process_update
    self.dispatch_error(None, update)
  File "/Library/Frameworks/Python.framework/Versions/3.8/lib/python3.8/site-packages/telegram/ext/dispatcher.py", line 810, in dispatch_error
    callback(update, context)
  File "/Users/hesdx/Documents/b95/tgfaucetbot/codec/tg.py", line 107, in error_handler
    context.bot.send_message(chat_id=self._developer, text=message, parse_mode=ParseMode.HTML)
NameError: name 'ParseMode' is not defined
2021-11-20 17:13:09,148 - telegram.ext.updater - ERROR - Error while getting Updates: Conflict: terminated by other getUpdates request; make sure that only one bot instance is running
2021-11-20 17:13:09,148 - codec.tg - ERROR - Exception while handling an update:
Traceback (most recent call last):
  File "/Library/Frameworks/Python.framework/Versions/3.8/lib/python3.8/site-packages/telegram/ext/updater.py", line 646, in _network_loop_retry
    if not action_cb():
  File "/Library/Frameworks/Python.framework/Versions/3.8/lib/python3.8/site-packages/telegram/ext/updater.py", line 597, in polling_action_cb
    updates = self.bot.get_updates(
  File "/Library/Frameworks/Python.framework/Versions/3.8/lib/python3.8/site-packages/telegram/ext/extbot.py", line 222, in get_updates
    updates = super().get_updates(
  File "/Library/Frameworks/Python.framework/Versions/3.8/lib/python3.8/site-packages/telegram/bot.py", line 130, in decorator
    result = func(*args, **kwargs)
  File "/Library/Frameworks/Python.framework/Versions/3.8/lib/python3.8/site-packages/telegram/bot.py", line 2861, in get_updates
    self._post(
  File "/Library/Frameworks/Python.framework/Versions/3.8/lib/python3.8/site-packages/telegram/bot.py", line 295, in _post
    return self.request.post(
  File "/Library/Frameworks/Python.framework/Versions/3.8/lib/python3.8/site-packages/telegram/utils/request.py", line 361, in post
    result = self._request_wrapper(
  File "/Library/Frameworks/Python.framework/Versions/3.8/lib/python3.8/site-packages/telegram/utils/request.py", line 283, in _request_wrapper
    raise Conflict(message)
telegram.error.Conflict: Conflict: terminated by other getUpdates request; make sure that only one bot instance is running
2021-11-20 17:13:09,149 - telegram.ext.dispatcher - ERROR - An uncaught error was raised while handling the error.
Traceback (most recent call last):
  File "/Library/Frameworks/Python.framework/Versions/3.8/lib/python3.8/site-packages/telegram/ext/dispatcher.py", line 536, in process_update
    self.dispatch_error(None, update)
  File "/Library/Frameworks/Python.framework/Versions/3.8/lib/python3.8/site-packages/telegram/ext/dispatcher.py", line 810, in dispatch_error
    callback(update, context)
  File "/Users/hesdx/Documents/b95/tgfaucetbot/codec/tg.py", line 107, in error_handler
    context.bot.send_message(chat_id=self._developer, text=message, parse_mode=ParseMode.HTML)
NameError: name 'ParseMode' is not defined
2021-11-20 17:13:15,717 - telegram.ext.updater - ERROR - Error while getting Updates: Conflict: terminated by other getUpdates request; make sure that only one bot instance is running
2021-11-20 17:13:15,718 - codec.tg - ERROR - Exception while handling an update:
Traceback (most recent call last):
  File "/Library/Frameworks/Python.framework/Versions/3.8/lib/python3.8/site-packages/telegram/ext/updater.py", line 646, in _network_loop_retry
    if not action_cb():
  File "/Library/Frameworks/Python.framework/Versions/3.8/lib/python3.8/site-packages/telegram/ext/updater.py", line 597, in polling_action_cb
    updates = self.bot.get_updates(
  File "/Library/Frameworks/Python.framework/Versions/3.8/lib/python3.8/site-packages/telegram/ext/extbot.py", line 222, in get_updates
    updates = super().get_updates(
  File "/Library/Frameworks/Python.framework/Versions/3.8/lib/python3.8/site-packages/telegram/bot.py", line 130, in decorator
    result = func(*args, **kwargs)
  File "/Library/Frameworks/Python.framework/Versions/3.8/lib/python3.8/site-packages/telegram/bot.py", line 2861, in get_updates
    self._post(
  File "/Library/Frameworks/Python.framework/Versions/3.8/lib/python3.8/site-packages/telegram/bot.py", line 295, in _post
    return self.request.post(
  File "/Library/Frameworks/Python.framework/Versions/3.8/lib/python3.8/site-packages/telegram/utils/request.py", line 361, in post
    result = self._request_wrapper(
  File "/Library/Frameworks/Python.framework/Versions/3.8/lib/python3.8/site-packages/telegram/utils/request.py", line 283, in _request_wrapper
    raise Conflict(message)
telegram.error.Conflict: Conflict: terminated by other getUpdates request; make sure that only one bot instance is running
2021-11-20 17:13:15,718 - telegram.ext.dispatcher - ERROR - An uncaught error was raised while handling the error.
Traceback (most recent call last):
  File "/Library/Frameworks/Python.framework/Versions/3.8/lib/python3.8/site-packages/telegram/ext/dispatcher.py", line 536, in process_update
    self.dispatch_error(None, update)
  File "/Library/Frameworks/Python.framework/Versions/3.8/lib/python3.8/site-packages/telegram/ext/dispatcher.py", line 810, in dispatch_error
    callback(update, context)
  File "/Users/hesdx/Documents/b95/tgfaucetbot/codec/tg.py", line 107, in error_handler
    context.bot.send_message(chat_id=self._developer, text=message, parse_mode=ParseMode.HTML)
NameError: name 'ParseMode' is not defined
2021-11-20 17:13:23,851 - telegram.ext.updater - ERROR - Error while getting Updates: Conflict: terminated by other getUpdates request; make sure that only one bot instance is running
2021-11-20 17:13:23,851 - codec.tg - ERROR - Exception while handling an update:
Traceback (most recent call last):
  File "/Library/Frameworks/Python.framework/Versions/3.8/lib/python3.8/site-packages/telegram/ext/updater.py", line 646, in _network_loop_retry
    if not action_cb():
  File "/Library/Frameworks/Python.framework/Versions/3.8/lib/python3.8/site-packages/telegram/ext/updater.py", line 597, in polling_action_cb
    updates = self.bot.get_updates(
  File "/Library/Frameworks/Python.framework/Versions/3.8/lib/python3.8/site-packages/telegram/ext/extbot.py", line 222, in get_updates
    updates = super().get_updates(
  File "/Library/Frameworks/Python.framework/Versions/3.8/lib/python3.8/site-packages/telegram/bot.py", line 130, in decorator
    result = func(*args, **kwargs)
  File "/Library/Frameworks/Python.framework/Versions/3.8/lib/python3.8/site-packages/telegram/bot.py", line 2861, in get_updates
    self._post(
  File "/Library/Frameworks/Python.framework/Versions/3.8/lib/python3.8/site-packages/telegram/bot.py", line 295, in _post
    return self.request.post(
  File "/Library/Frameworks/Python.framework/Versions/3.8/lib/python3.8/site-packages/telegram/utils/request.py", line 361, in post
    result = self._request_wrapper(
  File "/Library/Frameworks/Python.framework/Versions/3.8/lib/python3.8/site-packages/telegram/utils/request.py", line 283, in _request_wrapper
    raise Conflict(message)
telegram.error.Conflict: Conflict: terminated by other getUpdates request; make sure that only one bot instance is running
2021-11-20 17:13:23,852 - telegram.ext.dispatcher - ERROR - An uncaught error was raised while handling the error.
Traceback (most recent call last):
  File "/Library/Frameworks/Python.framework/Versions/3.8/lib/python3.8/site-packages/telegram/ext/dispatcher.py", line 536, in process_update
    self.dispatch_error(None, update)
  File "/Library/Frameworks/Python.framework/Versions/3.8/lib/python3.8/site-packages/telegram/ext/dispatcher.py", line 810, in dispatch_error
    callback(update, context)
  File "/Users/hesdx/Documents/b95/tgfaucetbot/codec/tg.py", line 107, in error_handler
    context.bot.send_message(chat_id=self._developer, text=message, parse_mode=ParseMode.HTML)
NameError: name 'ParseMode' is not defined
2021-11-20 17:13:31,121 - telegram.ext.updater - ERROR - Error while getting Updates: Conflict: terminated by other getUpdates request; make sure that only one bot instance is running
2021-11-20 17:13:31,121 - codec.tg - ERROR - Exception while handling an update:
Traceback (most recent call last):
  File "/Library/Frameworks/Python.framework/Versions/3.8/lib/python3.8/site-packages/telegram/ext/updater.py", line 646, in _network_loop_retry
    if not action_cb():
  File "/Library/Frameworks/Python.framework/Versions/3.8/lib/python3.8/site-packages/telegram/ext/updater.py", line 597, in polling_action_cb
    updates = self.bot.get_updates(
  File "/Library/Frameworks/Python.framework/Versions/3.8/lib/python3.8/site-packages/telegram/ext/extbot.py", line 222, in get_updates
    updates = super().get_updates(
  File "/Library/Frameworks/Python.framework/Versions/3.8/lib/python3.8/site-packages/telegram/bot.py", line 130, in decorator
    result = func(*args, **kwargs)
  File "/Library/Frameworks/Python.framework/Versions/3.8/lib/python3.8/site-packages/telegram/bot.py", line 2861, in get_updates
    self._post(
  File "/Library/Frameworks/Python.framework/Versions/3.8/lib/python3.8/site-packages/telegram/bot.py", line 295, in _post
    return self.request.post(
  File "/Library/Frameworks/Python.framework/Versions/3.8/lib/python3.8/site-packages/telegram/utils/request.py", line 361, in post
    result = self._request_wrapper(
  File "/Library/Frameworks/Python.framework/Versions/3.8/lib/python3.8/site-packages/telegram/utils/request.py", line 283, in _request_wrapper
    raise Conflict(message)
telegram.error.Conflict: Conflict: terminated by other getUpdates request; make sure that only one bot instance is running
2021-11-20 17:13:31,121 - telegram.ext.dispatcher - ERROR - An uncaught error was raised while handling the error.
Traceback (most recent call last):
  File "/Library/Frameworks/Python.framework/Versions/3.8/lib/python3.8/site-packages/telegram/ext/dispatcher.py", line 536, in process_update
    self.dispatch_error(None, update)
  File "/Library/Frameworks/Python.framework/Versions/3.8/lib/python3.8/site-packages/telegram/ext/dispatcher.py", line 810, in dispatch_error
    callback(update, context)
  File "/Users/hesdx/Documents/b95/tgfaucetbot/codec/tg.py", line 107, in error_handler
    context.bot.send_message(chat_id=self._developer, text=message, parse_mode=ParseMode.HTML)
NameError: name 'ParseMode' is not defined
2021-11-20 17:13:41,780 - telegram.ext.updater - ERROR - Error while getting Updates: Conflict: terminated by other getUpdates request; make sure that only one bot instance is running
2021-11-20 17:13:41,780 - codec.tg - ERROR - Exception while handling an update:
Traceback (most recent call last):
  File "/Library/Frameworks/Python.framework/Versions/3.8/lib/python3.8/site-packages/telegram/ext/updater.py", line 646, in _network_loop_retry
    if not action_cb():
  File "/Library/Frameworks/Python.framework/Versions/3.8/lib/python3.8/site-packages/telegram/ext/updater.py", line 597, in polling_action_cb
    updates = self.bot.get_updates(
  File "/Library/Frameworks/Python.framework/Versions/3.8/lib/python3.8/site-packages/telegram/ext/extbot.py", line 222, in get_updates
    updates = super().get_updates(
  File "/Library/Frameworks/Python.framework/Versions/3.8/lib/python3.8/site-packages/telegram/bot.py", line 130, in decorator
    result = func(*args, **kwargs)
  File "/Library/Frameworks/Python.framework/Versions/3.8/lib/python3.8/site-packages/telegram/bot.py", line 2861, in get_updates
    self._post(
  File "/Library/Frameworks/Python.framework/Versions/3.8/lib/python3.8/site-packages/telegram/bot.py", line 295, in _post
    return self.request.post(
  File "/Library/Frameworks/Python.framework/Versions/3.8/lib/python3.8/site-packages/telegram/utils/request.py", line 361, in post
    result = self._request_wrapper(
  File "/Library/Frameworks/Python.framework/Versions/3.8/lib/python3.8/site-packages/telegram/utils/request.py", line 283, in _request_wrapper
    raise Conflict(message)
telegram.error.Conflict: Conflict: terminated by other getUpdates request; make sure that only one bot instance is running
2021-11-20 17:13:41,781 - telegram.ext.dispatcher - ERROR - An uncaught error was raised while handling the error.
Traceback (most recent call last):
  File "/Library/Frameworks/Python.framework/Versions/3.8/lib/python3.8/site-packages/telegram/ext/dispatcher.py", line 536, in process_update
    self.dispatch_error(None, update)
  File "/Library/Frameworks/Python.framework/Versions/3.8/lib/python3.8/site-packages/telegram/ext/dispatcher.py", line 810, in dispatch_error
    callback(update, context)
  File "/Users/hesdx/Documents/b95/tgfaucetbot/codec/tg.py", line 107, in error_handler
    context.bot.send_message(chat_id=self._developer, text=message, parse_mode=ParseMode.HTML)
NameError: name 'ParseMode' is not defined
2021-11-20 17:13:57,500 - telegram.ext.updater - ERROR - Error while getting Updates: Conflict: terminated by other getUpdates request; make sure that only one bot instance is running
2021-11-20 17:13:57,501 - codec.tg - ERROR - Exception while handling an update:
Traceback (most recent call last):
  File "/Library/Frameworks/Python.framework/Versions/3.8/lib/python3.8/site-packages/telegram/ext/updater.py", line 646, in _network_loop_retry
    if not action_cb():
  File "/Library/Frameworks/Python.framework/Versions/3.8/lib/python3.8/site-packages/telegram/ext/updater.py", line 597, in polling_action_cb
    updates = self.bot.get_updates(
  File "/Library/Frameworks/Python.framework/Versions/3.8/lib/python3.8/site-packages/telegram/ext/extbot.py", line 222, in get_updates
    updates = super().get_updates(
  File "/Library/Frameworks/Python.framework/Versions/3.8/lib/python3.8/site-packages/telegram/bot.py", line 130, in decorator
    result = func(*args, **kwargs)
  File "/Library/Frameworks/Python.framework/Versions/3.8/lib/python3.8/site-packages/telegram/bot.py", line 2861, in get_updates
    self._post(
  File "/Library/Frameworks/Python.framework/Versions/3.8/lib/python3.8/site-packages/telegram/bot.py", line 295, in _post
    return self.request.post(
  File "/Library/Frameworks/Python.framework/Versions/3.8/lib/python3.8/site-packages/telegram/utils/request.py", line 361, in post
    result = self._request_wrapper(
  File "/Library/Frameworks/Python.framework/Versions/3.8/lib/python3.8/site-packages/telegram/utils/request.py", line 283, in _request_wrapper
    raise Conflict(message)
telegram.error.Conflict: Conflict: terminated by other getUpdates request; make sure that only one bot instance is running
2021-11-20 17:13:57,502 - telegram.ext.dispatcher - ERROR - An uncaught error was raised while handling the error.
Traceback (most recent call last):
  File "/Library/Frameworks/Python.framework/Versions/3.8/lib/python3.8/site-packages/telegram/ext/dispatcher.py", line 536, in process_update
    self.dispatch_error(None, update)
  File "/Library/Frameworks/Python.framework/Versions/3.8/lib/python3.8/site-packages/telegram/ext/dispatcher.py", line 810, in dispatch_error
    callback(update, context)
  File "/Users/hesdx/Documents/b95/tgfaucetbot/codec/tg.py", line 107, in error_handler
    context.bot.send_message(chat_id=self._developer, text=message, parse_mode=ParseMode.HTML)
NameError: name 'ParseMode' is not defined
2021-11-20 17:14:13,457 - telegram.ext.updater - ERROR - Error while getting Updates: Conflict: terminated by other getUpdates request; make sure that only one bot instance is running
2021-11-20 17:14:13,457 - codec.tg - ERROR - Exception while handling an update:
Traceback (most recent call last):
  File "/Library/Frameworks/Python.framework/Versions/3.8/lib/python3.8/site-packages/telegram/ext/updater.py", line 646, in _network_loop_retry
    if not action_cb():
  File "/Library/Frameworks/Python.framework/Versions/3.8/lib/python3.8/site-packages/telegram/ext/updater.py", line 597, in polling_action_cb
    updates = self.bot.get_updates(
  File "/Library/Frameworks/Python.framework/Versions/3.8/lib/python3.8/site-packages/telegram/ext/extbot.py", line 222, in get_updates
    updates = super().get_updates(
  File "/Library/Frameworks/Python.framework/Versions/3.8/lib/python3.8/site-packages/telegram/bot.py", line 130, in decorator
    result = func(*args, **kwargs)
  File "/Library/Frameworks/Python.framework/Versions/3.8/lib/python3.8/site-packages/telegram/bot.py", line 2861, in get_updates
    self._post(
  File "/Library/Frameworks/Python.framework/Versions/3.8/lib/python3.8/site-packages/telegram/bot.py", line 295, in _post
    return self.request.post(
  File "/Library/Frameworks/Python.framework/Versions/3.8/lib/python3.8/site-packages/telegram/utils/request.py", line 361, in post
    result = self._request_wrapper(
  File "/Library/Frameworks/Python.framework/Versions/3.8/lib/python3.8/site-packages/telegram/utils/request.py", line 283, in _request_wrapper
    raise Conflict(message)
telegram.error.Conflict: Conflict: terminated by other getUpdates request; make sure that only one bot instance is running
2021-11-20 17:14:13,457 - telegram.ext.dispatcher - ERROR - An uncaught error was raised while handling the error.
Traceback (most recent call last):
  File "/Library/Frameworks/Python.framework/Versions/3.8/lib/python3.8/site-packages/telegram/ext/dispatcher.py", line 536, in process_update
    self.dispatch_error(None, update)
  File "/Library/Frameworks/Python.framework/Versions/3.8/lib/python3.8/site-packages/telegram/ext/dispatcher.py", line 810, in dispatch_error
    callback(update, context)
  File "/Users/hesdx/Documents/b95/tgfaucetbot/codec/tg.py", line 107, in error_handler
    context.bot.send_message(chat_id=self._developer, text=message, parse_mode=ParseMode.HTML)
NameError: name 'ParseMode' is not defined
2021-11-20 17:14:30,965 - telegram.ext.updater - ERROR - Error while getting Updates: Conflict: terminated by other getUpdates request; make sure that only one bot instance is running
2021-11-20 17:14:30,965 - codec.tg - ERROR - Exception while handling an update:
Traceback (most recent call last):
  File "/Library/Frameworks/Python.framework/Versions/3.8/lib/python3.8/site-packages/telegram/ext/updater.py", line 646, in _network_loop_retry
    if not action_cb():
  File "/Library/Frameworks/Python.framework/Versions/3.8/lib/python3.8/site-packages/telegram/ext/updater.py", line 597, in polling_action_cb
    updates = self.bot.get_updates(
  File "/Library/Frameworks/Python.framework/Versions/3.8/lib/python3.8/site-packages/telegram/ext/extbot.py", line 222, in get_updates
    updates = super().get_updates(
  File "/Library/Frameworks/Python.framework/Versions/3.8/lib/python3.8/site-packages/telegram/bot.py", line 130, in decorator
    result = func(*args, **kwargs)
  File "/Library/Frameworks/Python.framework/Versions/3.8/lib/python3.8/site-packages/telegram/bot.py", line 2861, in get_updates
    self._post(
  File "/Library/Frameworks/Python.framework/Versions/3.8/lib/python3.8/site-packages/telegram/bot.py", line 295, in _post
    return self.request.post(
  File "/Library/Frameworks/Python.framework/Versions/3.8/lib/python3.8/site-packages/telegram/utils/request.py", line 361, in post
    result = self._request_wrapper(
  File "/Library/Frameworks/Python.framework/Versions/3.8/lib/python3.8/site-packages/telegram/utils/request.py", line 283, in _request_wrapper
    raise Conflict(message)
telegram.error.Conflict: Conflict: terminated by other getUpdates request; make sure that only one bot instance is running
2021-11-20 17:14:30,966 - telegram.ext.dispatcher - ERROR - An uncaught error was raised while handling the error.
Traceback (most recent call last):
  File "/Library/Frameworks/Python.framework/Versions/3.8/lib/python3.8/site-packages/telegram/ext/dispatcher.py", line 536, in process_update
    self.dispatch_error(None, update)
  File "/Library/Frameworks/Python.framework/Versions/3.8/lib/python3.8/site-packages/telegram/ext/dispatcher.py", line 810, in dispatch_error
    callback(update, context)
  File "/Users/hesdx/Documents/b95/tgfaucetbot/codec/tg.py", line 107, in error_handler
    context.bot.send_message(chat_id=self._developer, text=message, parse_mode=ParseMode.HTML)
NameError: name 'ParseMode' is not defined
2021-11-20 17:15:01,276 - telegram.ext.updater - ERROR - Error while getting Updates: Conflict: terminated by other getUpdates request; make sure that only one bot instance is running
2021-11-20 17:15:01,276 - codec.tg - ERROR - Exception while handling an update:
Traceback (most recent call last):
  File "/Library/Frameworks/Python.framework/Versions/3.8/lib/python3.8/site-packages/telegram/ext/updater.py", line 646, in _network_loop_retry
    if not action_cb():
  File "/Library/Frameworks/Python.framework/Versions/3.8/lib/python3.8/site-packages/telegram/ext/updater.py", line 597, in polling_action_cb
    updates = self.bot.get_updates(
  File "/Library/Frameworks/Python.framework/Versions/3.8/lib/python3.8/site-packages/telegram/ext/extbot.py", line 222, in get_updates
    updates = super().get_updates(
  File "/Library/Frameworks/Python.framework/Versions/3.8/lib/python3.8/site-packages/telegram/bot.py", line 130, in decorator
    result = func(*args, **kwargs)
  File "/Library/Frameworks/Python.framework/Versions/3.8/lib/python3.8/site-packages/telegram/bot.py", line 2861, in get_updates
    self._post(
  File "/Library/Frameworks/Python.framework/Versions/3.8/lib/python3.8/site-packages/telegram/bot.py", line 295, in _post
    return self.request.post(
  File "/Library/Frameworks/Python.framework/Versions/3.8/lib/python3.8/site-packages/telegram/utils/request.py", line 361, in post
    result = self._request_wrapper(
  File "/Library/Frameworks/Python.framework/Versions/3.8/lib/python3.8/site-packages/telegram/utils/request.py", line 283, in _request_wrapper
    raise Conflict(message)
telegram.error.Conflict: Conflict: terminated by other getUpdates request; make sure that only one bot instance is running
2021-11-20 17:15:01,277 - telegram.ext.dispatcher - ERROR - An uncaught error was raised while handling the error.
Traceback (most recent call last):
  File "/Library/Frameworks/Python.framework/Versions/3.8/lib/python3.8/site-packages/telegram/ext/dispatcher.py", line 536, in process_update
    self.dispatch_error(None, update)
  File "/Library/Frameworks/Python.framework/Versions/3.8/lib/python3.8/site-packages/telegram/ext/dispatcher.py", line 810, in dispatch_error
    callback(update, context)
  File "/Users/hesdx/Documents/b95/tgfaucetbot/codec/tg.py", line 107, in error_handler
    context.bot.send_message(chat_id=self._developer, text=message, parse_mode=ParseMode.HTML)
NameError: name 'ParseMode' is not defined
2021-11-20 17:15:44,284 - telegram.ext.updater - ERROR - Error while getting Updates: Conflict: terminated by other getUpdates request; make sure that only one bot instance is running
2021-11-20 17:15:44,284 - codec.tg - ERROR - Exception while handling an update:
Traceback (most recent call last):
  File "/Library/Frameworks/Python.framework/Versions/3.8/lib/python3.8/site-packages/telegram/ext/updater.py", line 646, in _network_loop_retry
    if not action_cb():
  File "/Library/Frameworks/Python.framework/Versions/3.8/lib/python3.8/site-packages/telegram/ext/updater.py", line 597, in polling_action_cb
    updates = self.bot.get_updates(
  File "/Library/Frameworks/Python.framework/Versions/3.8/lib/python3.8/site-packages/telegram/ext/extbot.py", line 222, in get_updates
    updates = super().get_updates(
  File "/Library/Frameworks/Python.framework/Versions/3.8/lib/python3.8/site-packages/telegram/bot.py", line 130, in decorator
    result = func(*args, **kwargs)
  File "/Library/Frameworks/Python.framework/Versions/3.8/lib/python3.8/site-packages/telegram/bot.py", line 2861, in get_updates
    self._post(
  File "/Library/Frameworks/Python.framework/Versions/3.8/lib/python3.8/site-packages/telegram/bot.py", line 295, in _post
    return self.request.post(
  File "/Library/Frameworks/Python.framework/Versions/3.8/lib/python3.8/site-packages/telegram/utils/request.py", line 361, in post
    result = self._request_wrapper(
  File "/Library/Frameworks/Python.framework/Versions/3.8/lib/python3.8/site-packages/telegram/utils/request.py", line 283, in _request_wrapper
    raise Conflict(message)
telegram.error.Conflict: Conflict: terminated by other getUpdates request; make sure that only one bot instance is running
2021-11-20 17:15:44,285 - telegram.ext.dispatcher - ERROR - An uncaught error was raised while handling the error.
Traceback (most recent call last):
  File "/Library/Frameworks/Python.framework/Versions/3.8/lib/python3.8/site-packages/telegram/ext/dispatcher.py", line 536, in process_update
    self.dispatch_error(None, update)
  File "/Library/Frameworks/Python.framework/Versions/3.8/lib/python3.8/site-packages/telegram/ext/dispatcher.py", line 810, in dispatch_error
    callback(update, context)
  File "/Users/hesdx/Documents/b95/tgfaucetbot/codec/tg.py", line 107, in error_handler
    context.bot.send_message(chat_id=self._developer, text=message, parse_mode=ParseMode.HTML)
NameError: name 'ParseMode' is not defined
2021-11-20 17:16:18,804 - telegram.ext.updater - ERROR - Error while getting Updates: Conflict: terminated by other getUpdates request; make sure that only one bot instance is running
2021-11-20 17:16:18,804 - codec.tg - ERROR - Exception while handling an update:
Traceback (most recent call last):
  File "/Library/Frameworks/Python.framework/Versions/3.8/lib/python3.8/site-packages/telegram/ext/updater.py", line 646, in _network_loop_retry
    if not action_cb():
  File "/Library/Frameworks/Python.framework/Versions/3.8/lib/python3.8/site-packages/telegram/ext/updater.py", line 597, in polling_action_cb
    updates = self.bot.get_updates(
  File "/Library/Frameworks/Python.framework/Versions/3.8/lib/python3.8/site-packages/telegram/ext/extbot.py", line 222, in get_updates
    updates = super().get_updates(
  File "/Library/Frameworks/Python.framework/Versions/3.8/lib/python3.8/site-packages/telegram/bot.py", line 130, in decorator
    result = func(*args, **kwargs)
  File "/Library/Frameworks/Python.framework/Versions/3.8/lib/python3.8/site-packages/telegram/bot.py", line 2861, in get_updates
    self._post(
  File "/Library/Frameworks/Python.framework/Versions/3.8/lib/python3.8/site-packages/telegram/bot.py", line 295, in _post
    return self.request.post(
  File "/Library/Frameworks/Python.framework/Versions/3.8/lib/python3.8/site-packages/telegram/utils/request.py", line 361, in post
    result = self._request_wrapper(
  File "/Library/Frameworks/Python.framework/Versions/3.8/lib/python3.8/site-packages/telegram/utils/request.py", line 283, in _request_wrapper
    raise Conflict(message)
telegram.error.Conflict: Conflict: terminated by other getUpdates request; make sure that only one bot instance is running
2021-11-20 17:16:18,804 - telegram.ext.dispatcher - ERROR - An uncaught error was raised while handling the error.
Traceback (most recent call last):
  File "/Library/Frameworks/Python.framework/Versions/3.8/lib/python3.8/site-packages/telegram/ext/dispatcher.py", line 536, in process_update
    self.dispatch_error(None, update)
  File "/Library/Frameworks/Python.framework/Versions/3.8/lib/python3.8/site-packages/telegram/ext/dispatcher.py", line 810, in dispatch_error
    callback(update, context)
  File "/Users/hesdx/Documents/b95/tgfaucetbot/codec/tg.py", line 107, in error_handler
    context.bot.send_message(chat_id=self._developer, text=message, parse_mode=ParseMode.HTML)
NameError: name 'ParseMode' is not defined
2021-11-20 17:16:53,403 - telegram.ext.updater - ERROR - Error while getting Updates: Conflict: terminated by other getUpdates request; make sure that only one bot instance is running
2021-11-20 17:16:53,403 - codec.tg - ERROR - Exception while handling an update:
Traceback (most recent call last):
  File "/Library/Frameworks/Python.framework/Versions/3.8/lib/python3.8/site-packages/telegram/ext/updater.py", line 646, in _network_loop_retry
    if not action_cb():
  File "/Library/Frameworks/Python.framework/Versions/3.8/lib/python3.8/site-packages/telegram/ext/updater.py", line 597, in polling_action_cb
    updates = self.bot.get_updates(
  File "/Library/Frameworks/Python.framework/Versions/3.8/lib/python3.8/site-packages/telegram/ext/extbot.py", line 222, in get_updates
    updates = super().get_updates(
  File "/Library/Frameworks/Python.framework/Versions/3.8/lib/python3.8/site-packages/telegram/bot.py", line 130, in decorator
    result = func(*args, **kwargs)
  File "/Library/Frameworks/Python.framework/Versions/3.8/lib/python3.8/site-packages/telegram/bot.py", line 2861, in get_updates
    self._post(
  File "/Library/Frameworks/Python.framework/Versions/3.8/lib/python3.8/site-packages/telegram/bot.py", line 295, in _post
    return self.request.post(
  File "/Library/Frameworks/Python.framework/Versions/3.8/lib/python3.8/site-packages/telegram/utils/request.py", line 361, in post
    result = self._request_wrapper(
  File "/Library/Frameworks/Python.framework/Versions/3.8/lib/python3.8/site-packages/telegram/utils/request.py", line 283, in _request_wrapper
    raise Conflict(message)
telegram.error.Conflict: Conflict: terminated by other getUpdates request; make sure that only one bot instance is running
2021-11-20 17:16:53,404 - telegram.ext.dispatcher - ERROR - An uncaught error was raised while handling the error.
Traceback (most recent call last):
  File "/Library/Frameworks/Python.framework/Versions/3.8/lib/python3.8/site-packages/telegram/ext/dispatcher.py", line 536, in process_update
    self.dispatch_error(None, update)
  File "/Library/Frameworks/Python.framework/Versions/3.8/lib/python3.8/site-packages/telegram/ext/dispatcher.py", line 810, in dispatch_error
    callback(update, context)
  File "/Users/hesdx/Documents/b95/tgfaucetbot/codec/tg.py", line 107, in error_handler
    context.bot.send_message(chat_id=self._developer, text=message, parse_mode=ParseMode.HTML)
NameError: name 'ParseMode' is not defined
2021-11-20 17:17:27,974 - telegram.ext.updater - ERROR - Error while getting Updates: Conflict: terminated by other getUpdates request; make sure that only one bot instance is running
2021-11-20 17:17:27,975 - codec.tg - ERROR - Exception while handling an update:
Traceback (most recent call last):
  File "/Library/Frameworks/Python.framework/Versions/3.8/lib/python3.8/site-packages/telegram/ext/updater.py", line 646, in _network_loop_retry
    if not action_cb():
  File "/Library/Frameworks/Python.framework/Versions/3.8/lib/python3.8/site-packages/telegram/ext/updater.py", line 597, in polling_action_cb
    updates = self.bot.get_updates(
  File "/Library/Frameworks/Python.framework/Versions/3.8/lib/python3.8/site-packages/telegram/ext/extbot.py", line 222, in get_updates
    updates = super().get_updates(
  File "/Library/Frameworks/Python.framework/Versions/3.8/lib/python3.8/site-packages/telegram/bot.py", line 130, in decorator
    result = func(*args, **kwargs)
  File "/Library/Frameworks/Python.framework/Versions/3.8/lib/python3.8/site-packages/telegram/bot.py", line 2861, in get_updates
    self._post(
  File "/Library/Frameworks/Python.framework/Versions/3.8/lib/python3.8/site-packages/telegram/bot.py", line 295, in _post
    return self.request.post(
  File "/Library/Frameworks/Python.framework/Versions/3.8/lib/python3.8/site-packages/telegram/utils/request.py", line 361, in post
    result = self._request_wrapper(
  File "/Library/Frameworks/Python.framework/Versions/3.8/lib/python3.8/site-packages/telegram/utils/request.py", line 283, in _request_wrapper
    raise Conflict(message)
telegram.error.Conflict: Conflict: terminated by other getUpdates request; make sure that only one bot instance is running
2021-11-20 17:17:27,975 - telegram.ext.dispatcher - ERROR - An uncaught error was raised while handling the error.
Traceback (most recent call last):
  File "/Library/Frameworks/Python.framework/Versions/3.8/lib/python3.8/site-packages/telegram/ext/dispatcher.py", line 536, in process_update
    self.dispatch_error(None, update)
  File "/Library/Frameworks/Python.framework/Versions/3.8/lib/python3.8/site-packages/telegram/ext/dispatcher.py", line 810, in dispatch_error
    callback(update, context)
  File "/Users/hesdx/Documents/b95/tgfaucetbot/codec/tg.py", line 107, in error_handler
    context.bot.send_message(chat_id=self._developer, text=message, parse_mode=ParseMode.HTML)
NameError: name 'ParseMode' is not defined
2021-11-20 17:19:17,624 - telegram.ext.updater - ERROR - Error while getting Updates: Conflict: terminated by other getUpdates request; make sure that only one bot instance is running
2021-11-20 17:19:17,624 - codec.tg - ERROR - Exception while handling an update:
Traceback (most recent call last):
  File "/Library/Frameworks/Python.framework/Versions/3.8/lib/python3.8/site-packages/telegram/ext/updater.py", line 646, in _network_loop_retry
    if not action_cb():
  File "/Library/Frameworks/Python.framework/Versions/3.8/lib/python3.8/site-packages/telegram/ext/updater.py", line 597, in polling_action_cb
    updates = self.bot.get_updates(
  File "/Library/Frameworks/Python.framework/Versions/3.8/lib/python3.8/site-packages/telegram/ext/extbot.py", line 222, in get_updates
    updates = super().get_updates(
  File "/Library/Frameworks/Python.framework/Versions/3.8/lib/python3.8/site-packages/telegram/bot.py", line 130, in decorator
    result = func(*args, **kwargs)
  File "/Library/Frameworks/Python.framework/Versions/3.8/lib/python3.8/site-packages/telegram/bot.py", line 2861, in get_updates
    self._post(
  File "/Library/Frameworks/Python.framework/Versions/3.8/lib/python3.8/site-packages/telegram/bot.py", line 295, in _post
    return self.request.post(
  File "/Library/Frameworks/Python.framework/Versions/3.8/lib/python3.8/site-packages/telegram/utils/request.py", line 361, in post
    result = self._request_wrapper(
  File "/Library/Frameworks/Python.framework/Versions/3.8/lib/python3.8/site-packages/telegram/utils/request.py", line 283, in _request_wrapper
    raise Conflict(message)
telegram.error.Conflict: Conflict: terminated by other getUpdates request; make sure that only one bot instance is running
2021-11-20 17:19:17,624 - telegram.ext.dispatcher - ERROR - An uncaught error was raised while handling the error.
Traceback (most recent call last):
  File "/Library/Frameworks/Python.framework/Versions/3.8/lib/python3.8/site-packages/telegram/ext/dispatcher.py", line 536, in process_update
    self.dispatch_error(None, update)
  File "/Library/Frameworks/Python.framework/Versions/3.8/lib/python3.8/site-packages/telegram/ext/dispatcher.py", line 810, in dispatch_error
    callback(update, context)
  File "/Users/hesdx/Documents/b95/tgfaucetbot/codec/tg.py", line 107, in error_handler
    context.bot.send_message(chat_id=self._developer, text=message, parse_mode=ParseMode.HTML)
NameError: name 'ParseMode' is not defined
2021-11-20 17:19:23,235 - telegram.ext.updater - ERROR - Error while getting Updates: Conflict: terminated by other getUpdates request; make sure that only one bot instance is running
2021-11-20 17:19:23,236 - codec.tg - ERROR - Exception while handling an update:
Traceback (most recent call last):
  File "/Library/Frameworks/Python.framework/Versions/3.8/lib/python3.8/site-packages/telegram/ext/updater.py", line 646, in _network_loop_retry
    if not action_cb():
  File "/Library/Frameworks/Python.framework/Versions/3.8/lib/python3.8/site-packages/telegram/ext/updater.py", line 597, in polling_action_cb
    updates = self.bot.get_updates(
  File "/Library/Frameworks/Python.framework/Versions/3.8/lib/python3.8/site-packages/telegram/ext/extbot.py", line 222, in get_updates
    updates = super().get_updates(
  File "/Library/Frameworks/Python.framework/Versions/3.8/lib/python3.8/site-packages/telegram/bot.py", line 130, in decorator
    result = func(*args, **kwargs)
  File "/Library/Frameworks/Python.framework/Versions/3.8/lib/python3.8/site-packages/telegram/bot.py", line 2861, in get_updates
    self._post(
  File "/Library/Frameworks/Python.framework/Versions/3.8/lib/python3.8/site-packages/telegram/bot.py", line 295, in _post
    return self.request.post(
  File "/Library/Frameworks/Python.framework/Versions/3.8/lib/python3.8/site-packages/telegram/utils/request.py", line 361, in post
    result = self._request_wrapper(
  File "/Library/Frameworks/Python.framework/Versions/3.8/lib/python3.8/site-packages/telegram/utils/request.py", line 283, in _request_wrapper
    raise Conflict(message)
telegram.error.Conflict: Conflict: terminated by other getUpdates request; make sure that only one bot instance is running
2021-11-20 17:19:23,236 - telegram.ext.dispatcher - ERROR - An uncaught error was raised while handling the error.
Traceback (most recent call last):
  File "/Library/Frameworks/Python.framework/Versions/3.8/lib/python3.8/site-packages/telegram/ext/dispatcher.py", line 536, in process_update
    self.dispatch_error(None, update)
  File "/Library/Frameworks/Python.framework/Versions/3.8/lib/python3.8/site-packages/telegram/ext/dispatcher.py", line 810, in dispatch_error
    callback(update, context)
  File "/Users/hesdx/Documents/b95/tgfaucetbot/codec/tg.py", line 107, in error_handler
    context.bot.send_message(chat_id=self._developer, text=message, parse_mode=ParseMode.HTML)
NameError: name 'ParseMode' is not defined
2021-11-20 17:19:29,838 - telegram.ext.updater - ERROR - Error while getting Updates: Conflict: terminated by other getUpdates request; make sure that only one bot instance is running
2021-11-20 17:19:29,838 - codec.tg - ERROR - Exception while handling an update:
Traceback (most recent call last):
  File "/Library/Frameworks/Python.framework/Versions/3.8/lib/python3.8/site-packages/telegram/ext/updater.py", line 646, in _network_loop_retry
    if not action_cb():
  File "/Library/Frameworks/Python.framework/Versions/3.8/lib/python3.8/site-packages/telegram/ext/updater.py", line 597, in polling_action_cb
    updates = self.bot.get_updates(
  File "/Library/Frameworks/Python.framework/Versions/3.8/lib/python3.8/site-packages/telegram/ext/extbot.py", line 222, in get_updates
    updates = super().get_updates(
  File "/Library/Frameworks/Python.framework/Versions/3.8/lib/python3.8/site-packages/telegram/bot.py", line 130, in decorator
    result = func(*args, **kwargs)
  File "/Library/Frameworks/Python.framework/Versions/3.8/lib/python3.8/site-packages/telegram/bot.py", line 2861, in get_updates
    self._post(
  File "/Library/Frameworks/Python.framework/Versions/3.8/lib/python3.8/site-packages/telegram/bot.py", line 295, in _post
    return self.request.post(
  File "/Library/Frameworks/Python.framework/Versions/3.8/lib/python3.8/site-packages/telegram/utils/request.py", line 361, in post
    result = self._request_wrapper(
  File "/Library/Frameworks/Python.framework/Versions/3.8/lib/python3.8/site-packages/telegram/utils/request.py", line 283, in _request_wrapper
    raise Conflict(message)
telegram.error.Conflict: Conflict: terminated by other getUpdates request; make sure that only one bot instance is running
2021-11-20 17:19:29,839 - telegram.ext.dispatcher - ERROR - An uncaught error was raised while handling the error.
Traceback (most recent call last):
  File "/Library/Frameworks/Python.framework/Versions/3.8/lib/python3.8/site-packages/telegram/ext/dispatcher.py", line 536, in process_update
    self.dispatch_error(None, update)
  File "/Library/Frameworks/Python.framework/Versions/3.8/lib/python3.8/site-packages/telegram/ext/dispatcher.py", line 810, in dispatch_error
    callback(update, context)
  File "/Users/hesdx/Documents/b95/tgfaucetbot/codec/tg.py", line 107, in error_handler
    context.bot.send_message(chat_id=self._developer, text=message, parse_mode=ParseMode.HTML)
NameError: name 'ParseMode' is not defined
2021-11-21 01:31:17,614 - telegram.vendor.ptb_urllib3.urllib3.connectionpool - WARNING - Retrying (Retry(total=2, connect=None, read=None, redirect=None)) after connection broken by 'ProxyError('Cannot connect to proxy.', timeout('_ssl.c:1106: The handshake operation timed out'))': /bot2070387982:AAFsSEVEQyFjplmKAPgaHOR9F5pa6TZKWz4/getUpdates
2021-11-21 08:35:48,699 - telegram.vendor.ptb_urllib3.urllib3.connectionpool - WARNING - Retrying (Retry(total=2, connect=None, read=None, redirect=None)) after connection broken by 'ProxyError('Cannot connect to proxy.', ConnectionResetError(54, 'Connection reset by peer'))': /bot2070387982:AAFsSEVEQyFjplmKAPgaHOR9F5pa6TZKWz4/getUpdates
2021-11-21 08:35:48,801 - telegram.vendor.ptb_urllib3.urllib3.connectionpool - WARNING - Retrying (Retry(total=1, connect=None, read=None, redirect=None)) after connection broken by 'ProxyError('Cannot connect to proxy.', ConnectionResetError(54, 'Connection reset by peer'))': /bot2070387982:AAFsSEVEQyFjplmKAPgaHOR9F5pa6TZKWz4/getUpdates
2021-11-21 08:35:48,835 - telegram.vendor.ptb_urllib3.urllib3.connectionpool - WARNING - Retrying (Retry(total=0, connect=None, read=None, redirect=None)) after connection broken by 'ProxyError('Cannot connect to proxy.', ConnectionResetError(54, 'Connection reset by peer'))': /bot2070387982:AAFsSEVEQyFjplmKAPgaHOR9F5pa6TZKWz4/getUpdates
2021-11-21 08:35:48,859 - telegram.ext.updater - ERROR - Error while getting Updates: urllib3 HTTPError HTTPSConnectionPool(host='api.telegram.org', port=443): Max retries exceeded with url: /bot2070387982:AAFsSEVEQyFjplmKAPgaHOR9F5pa6TZKWz4/getUpdates (Caused by ProxyError('Cannot connect to proxy.', OSError(0, 'Error')))
2021-11-21 08:35:48,961 - codec.tg - ERROR - Exception while handling an update:
Traceback (most recent call last):
  File "/Library/Frameworks/Python.framework/Versions/3.8/lib/python3.8/site-packages/telegram/vendor/ptb_urllib3/urllib3/connectionpool.py", line 611, in urlopen
    self._prepare_proxy(conn)
  File "/Library/Frameworks/Python.framework/Versions/3.8/lib/python3.8/site-packages/telegram/vendor/ptb_urllib3/urllib3/connectionpool.py", line 827, in _prepare_proxy
    conn.connect()
  File "/Library/Frameworks/Python.framework/Versions/3.8/lib/python3.8/site-packages/telegram/vendor/ptb_urllib3/urllib3/connection.py", line 319, in connect
    self.sock = ssl_wrap_socket(
  File "/Library/Frameworks/Python.framework/Versions/3.8/lib/python3.8/site-packages/telegram/vendor/ptb_urllib3/urllib3/util/ssl_.py", line 324, in ssl_wrap_socket
    return context.wrap_socket(sock, server_hostname=server_hostname)
  File "/Library/Frameworks/Python.framework/Versions/3.8/lib/python3.8/ssl.py", line 500, in wrap_socket
    return self.sslsocket_class._create(
  File "/Library/Frameworks/Python.framework/Versions/3.8/lib/python3.8/ssl.py", line 1040, in _create
    self.do_handshake()
  File "/Library/Frameworks/Python.framework/Versions/3.8/lib/python3.8/ssl.py", line 1309, in do_handshake
    self._sslobj.do_handshake()
OSError: [Errno 0] Error

During handling of the above exception, another exception occurred:

Traceback (most recent call last):
  File "/Library/Frameworks/Python.framework/Versions/3.8/lib/python3.8/site-packages/telegram/utils/request.py", line 259, in _request_wrapper
    resp = self._con_pool.request(*args, **kwargs)
  File "/Library/Frameworks/Python.framework/Versions/3.8/lib/python3.8/site-packages/telegram/vendor/ptb_urllib3/urllib3/request.py", line 68, in request
    return self.request_encode_body(method, url, fields=fields,
  File "/Library/Frameworks/Python.framework/Versions/3.8/lib/python3.8/site-packages/telegram/vendor/ptb_urllib3/urllib3/request.py", line 148, in request_encode_body
    return self.urlopen(method, url, **extra_kw)
  File "/Library/Frameworks/Python.framework/Versions/3.8/lib/python3.8/site-packages/telegram/vendor/ptb_urllib3/urllib3/poolmanager.py", line 359, in urlopen
    return super(ProxyManager, self).urlopen(method, url, redirect=redirect, **kw)
  File "/Library/Frameworks/Python.framework/Versions/3.8/lib/python3.8/site-packages/telegram/vendor/ptb_urllib3/urllib3/poolmanager.py", line 244, in urlopen
    response = conn.urlopen(method, u.request_uri, **kw)
  File "/Library/Frameworks/Python.framework/Versions/3.8/lib/python3.8/site-packages/telegram/vendor/ptb_urllib3/urllib3/connectionpool.py", line 691, in urlopen
    return self.urlopen(method, url, body, headers, retries,
  File "/Library/Frameworks/Python.framework/Versions/3.8/lib/python3.8/site-packages/telegram/vendor/ptb_urllib3/urllib3/connectionpool.py", line 691, in urlopen
    return self.urlopen(method, url, body, headers, retries,
  File "/Library/Frameworks/Python.framework/Versions/3.8/lib/python3.8/site-packages/telegram/vendor/ptb_urllib3/urllib3/connectionpool.py", line 691, in urlopen
    return self.urlopen(method, url, body, headers, retries,
  File "/Library/Frameworks/Python.framework/Versions/3.8/lib/python3.8/site-packages/telegram/vendor/ptb_urllib3/urllib3/connectionpool.py", line 665, in urlopen
    retries = retries.increment(method, url, error=e, _pool=self,
  File "/Library/Frameworks/Python.framework/Versions/3.8/lib/python3.8/site-packages/telegram/vendor/ptb_urllib3/urllib3/util/retry.py", line 376, in increment
    raise MaxRetryError(_pool, url, error or ResponseError(cause))
telegram.vendor.ptb_urllib3.urllib3.exceptions.MaxRetryError: HTTPSConnectionPool(host='api.telegram.org', port=443): Max retries exceeded with url: /bot2070387982:AAFsSEVEQyFjplmKAPgaHOR9F5pa6TZKWz4/getUpdates (Caused by ProxyError('Cannot connect to proxy.', OSError(0, 'Error')))

The above exception was the direct cause of the following exception:

Traceback (most recent call last):
  File "/Library/Frameworks/Python.framework/Versions/3.8/lib/python3.8/site-packages/telegram/ext/updater.py", line 646, in _network_loop_retry
    if not action_cb():
  File "/Library/Frameworks/Python.framework/Versions/3.8/lib/python3.8/site-packages/telegram/ext/updater.py", line 597, in polling_action_cb
    updates = self.bot.get_updates(
  File "/Library/Frameworks/Python.framework/Versions/3.8/lib/python3.8/site-packages/telegram/ext/extbot.py", line 222, in get_updates
    updates = super().get_updates(
  File "/Library/Frameworks/Python.framework/Versions/3.8/lib/python3.8/site-packages/telegram/bot.py", line 130, in decorator
    result = func(*args, **kwargs)
  File "/Library/Frameworks/Python.framework/Versions/3.8/lib/python3.8/site-packages/telegram/bot.py", line 2861, in get_updates
    self._post(
  File "/Library/Frameworks/Python.framework/Versions/3.8/lib/python3.8/site-packages/telegram/bot.py", line 295, in _post
    return self.request.post(
  File "/Library/Frameworks/Python.framework/Versions/3.8/lib/python3.8/site-packages/telegram/utils/request.py", line 361, in post
    result = self._request_wrapper(
  File "/Library/Frameworks/Python.framework/Versions/3.8/lib/python3.8/site-packages/telegram/utils/request.py", line 265, in _request_wrapper
    raise NetworkError(f'urllib3 HTTPError {error}') from error
telegram.error.NetworkError: urllib3 HTTPError HTTPSConnectionPool(host='api.telegram.org', port=443): Max retries exceeded with url: /bot2070387982:AAFsSEVEQyFjplmKAPgaHOR9F5pa6TZKWz4/getUpdates (Caused by ProxyError('Cannot connect to proxy.', OSError(0, 'Error')))
2021-11-21 08:35:48,984 - telegram.ext.dispatcher - ERROR - An uncaught error was raised while handling the error.
Traceback (most recent call last):
  File "/Library/Frameworks/Python.framework/Versions/3.8/lib/python3.8/site-packages/telegram/ext/dispatcher.py", line 536, in process_update
    self.dispatch_error(None, update)
  File "/Library/Frameworks/Python.framework/Versions/3.8/lib/python3.8/site-packages/telegram/ext/dispatcher.py", line 810, in dispatch_error
    callback(update, context)
  File "/Users/hesdx/Documents/b95/tgfaucetbot/codec/tg.py", line 107, in error_handler
    else:
NameError: name 'ParseMode' is not defined
2021-11-21 08:35:49,945 - telegram.vendor.ptb_urllib3.urllib3.connectionpool - WARNING - Retrying (Retry(total=2, connect=None, read=None, redirect=None)) after connection broken by 'ProxyError('Cannot connect to proxy.', OSError(0, 'Error'))': /bot2070387982:AAFsSEVEQyFjplmKAPgaHOR9F5pa6TZKWz4/getUpdates
2021-11-21 08:35:49,960 - telegram.vendor.ptb_urllib3.urllib3.connectionpool - WARNING - Retrying (Retry(total=1, connect=None, read=None, redirect=None)) after connection broken by 'ProxyError('Cannot connect to proxy.', OSError(0, 'Error'))': /bot2070387982:AAFsSEVEQyFjplmKAPgaHOR9F5pa6TZKWz4/getUpdates
2021-11-21 08:35:49,975 - telegram.vendor.ptb_urllib3.urllib3.connectionpool - WARNING - Retrying (Retry(total=0, connect=None, read=None, redirect=None)) after connection broken by 'ProxyError('Cannot connect to proxy.', OSError(0, 'Error'))': /bot2070387982:AAFsSEVEQyFjplmKAPgaHOR9F5pa6TZKWz4/getUpdates
2021-11-21 08:35:49,991 - telegram.ext.updater - ERROR - Error while getting Updates: urllib3 HTTPError HTTPSConnectionPool(host='api.telegram.org', port=443): Max retries exceeded with url: /bot2070387982:AAFsSEVEQyFjplmKAPgaHOR9F5pa6TZKWz4/getUpdates (Caused by ProxyError('Cannot connect to proxy.', OSError(0, 'Error')))
2021-11-21 08:35:49,994 - codec.tg - ERROR - Exception while handling an update:
Traceback (most recent call last):
  File "/Library/Frameworks/Python.framework/Versions/3.8/lib/python3.8/site-packages/telegram/vendor/ptb_urllib3/urllib3/connectionpool.py", line 611, in urlopen
    self._prepare_proxy(conn)
  File "/Library/Frameworks/Python.framework/Versions/3.8/lib/python3.8/site-packages/telegram/vendor/ptb_urllib3/urllib3/connectionpool.py", line 827, in _prepare_proxy
    conn.connect()
  File "/Library/Frameworks/Python.framework/Versions/3.8/lib/python3.8/site-packages/telegram/vendor/ptb_urllib3/urllib3/connection.py", line 319, in connect
    self.sock = ssl_wrap_socket(
  File "/Library/Frameworks/Python.framework/Versions/3.8/lib/python3.8/site-packages/telegram/vendor/ptb_urllib3/urllib3/util/ssl_.py", line 324, in ssl_wrap_socket
    return context.wrap_socket(sock, server_hostname=server_hostname)
  File "/Library/Frameworks/Python.framework/Versions/3.8/lib/python3.8/ssl.py", line 500, in wrap_socket
    return self.sslsocket_class._create(
  File "/Library/Frameworks/Python.framework/Versions/3.8/lib/python3.8/ssl.py", line 1040, in _create
    self.do_handshake()
  File "/Library/Frameworks/Python.framework/Versions/3.8/lib/python3.8/ssl.py", line 1309, in do_handshake
    self._sslobj.do_handshake()
OSError: [Errno 0] Error

During handling of the above exception, another exception occurred:

Traceback (most recent call last):
  File "/Library/Frameworks/Python.framework/Versions/3.8/lib/python3.8/site-packages/telegram/utils/request.py", line 259, in _request_wrapper
    resp = self._con_pool.request(*args, **kwargs)
  File "/Library/Frameworks/Python.framework/Versions/3.8/lib/python3.8/site-packages/telegram/vendor/ptb_urllib3/urllib3/request.py", line 68, in request
    return self.request_encode_body(method, url, fields=fields,
  File "/Library/Frameworks/Python.framework/Versions/3.8/lib/python3.8/site-packages/telegram/vendor/ptb_urllib3/urllib3/request.py", line 148, in request_encode_body
    return self.urlopen(method, url, **extra_kw)
  File "/Library/Frameworks/Python.framework/Versions/3.8/lib/python3.8/site-packages/telegram/vendor/ptb_urllib3/urllib3/poolmanager.py", line 359, in urlopen
    return super(ProxyManager, self).urlopen(method, url, redirect=redirect, **kw)
  File "/Library/Frameworks/Python.framework/Versions/3.8/lib/python3.8/site-packages/telegram/vendor/ptb_urllib3/urllib3/poolmanager.py", line 244, in urlopen
    response = conn.urlopen(method, u.request_uri, **kw)
  File "/Library/Frameworks/Python.framework/Versions/3.8/lib/python3.8/site-packages/telegram/vendor/ptb_urllib3/urllib3/connectionpool.py", line 691, in urlopen
    return self.urlopen(method, url, body, headers, retries,
  File "/Library/Frameworks/Python.framework/Versions/3.8/lib/python3.8/site-packages/telegram/vendor/ptb_urllib3/urllib3/connectionpool.py", line 691, in urlopen
    return self.urlopen(method, url, body, headers, retries,
  File "/Library/Frameworks/Python.framework/Versions/3.8/lib/python3.8/site-packages/telegram/vendor/ptb_urllib3/urllib3/connectionpool.py", line 691, in urlopen
    return self.urlopen(method, url, body, headers, retries,
  File "/Library/Frameworks/Python.framework/Versions/3.8/lib/python3.8/site-packages/telegram/vendor/ptb_urllib3/urllib3/connectionpool.py", line 665, in urlopen
    retries = retries.increment(method, url, error=e, _pool=self,
  File "/Library/Frameworks/Python.framework/Versions/3.8/lib/python3.8/site-packages/telegram/vendor/ptb_urllib3/urllib3/util/retry.py", line 376, in increment
    raise MaxRetryError(_pool, url, error or ResponseError(cause))
telegram.vendor.ptb_urllib3.urllib3.exceptions.MaxRetryError: HTTPSConnectionPool(host='api.telegram.org', port=443): Max retries exceeded with url: /bot2070387982:AAFsSEVEQyFjplmKAPgaHOR9F5pa6TZKWz4/getUpdates (Caused by ProxyError('Cannot connect to proxy.', OSError(0, 'Error')))

The above exception was the direct cause of the following exception:

Traceback (most recent call last):
  File "/Library/Frameworks/Python.framework/Versions/3.8/lib/python3.8/site-packages/telegram/ext/updater.py", line 646, in _network_loop_retry
    if not action_cb():
  File "/Library/Frameworks/Python.framework/Versions/3.8/lib/python3.8/site-packages/telegram/ext/updater.py", line 597, in polling_action_cb
    updates = self.bot.get_updates(
  File "/Library/Frameworks/Python.framework/Versions/3.8/lib/python3.8/site-packages/telegram/ext/extbot.py", line 222, in get_updates
    updates = super().get_updates(
  File "/Library/Frameworks/Python.framework/Versions/3.8/lib/python3.8/site-packages/telegram/bot.py", line 130, in decorator
    result = func(*args, **kwargs)
  File "/Library/Frameworks/Python.framework/Versions/3.8/lib/python3.8/site-packages/telegram/bot.py", line 2861, in get_updates
    self._post(
  File "/Library/Frameworks/Python.framework/Versions/3.8/lib/python3.8/site-packages/telegram/bot.py", line 295, in _post
    return self.request.post(
  File "/Library/Frameworks/Python.framework/Versions/3.8/lib/python3.8/site-packages/telegram/utils/request.py", line 361, in post
    result = self._request_wrapper(
  File "/Library/Frameworks/Python.framework/Versions/3.8/lib/python3.8/site-packages/telegram/utils/request.py", line 265, in _request_wrapper
    raise NetworkError(f'urllib3 HTTPError {error}') from error
telegram.error.NetworkError: urllib3 HTTPError HTTPSConnectionPool(host='api.telegram.org', port=443): Max retries exceeded with url: /bot2070387982:AAFsSEVEQyFjplmKAPgaHOR9F5pa6TZKWz4/getUpdates (Caused by ProxyError('Cannot connect to proxy.', OSError(0, 'Error')))
2021-11-21 08:35:49,996 - telegram.ext.dispatcher - ERROR - An uncaught error was raised while handling the error.
Traceback (most recent call last):
  File "/Library/Frameworks/Python.framework/Versions/3.8/lib/python3.8/site-packages/telegram/ext/dispatcher.py", line 536, in process_update
    self.dispatch_error(None, update)
  File "/Library/Frameworks/Python.framework/Versions/3.8/lib/python3.8/site-packages/telegram/ext/dispatcher.py", line 810, in dispatch_error
    callback(update, context)
  File "/Users/hesdx/Documents/b95/tgfaucetbot/codec/tg.py", line 107, in error_handler
    else:
NameError: name 'ParseMode' is not defined
2021-11-21 08:35:56,609 - telegram.vendor.ptb_urllib3.urllib3.connectionpool - WARNING - Retrying (Retry(total=2, connect=None, read=None, redirect=None)) after connection broken by 'ProxyError('Cannot connect to proxy.', timeout('_ssl.c:1106: The handshake operation timed out'))': /bot2070387982:AAFsSEVEQyFjplmKAPgaHOR9F5pa6TZKWz4/getUpdates
2021-11-21 08:36:01,629 - telegram.vendor.ptb_urllib3.urllib3.connectionpool - WARNING - Retrying (Retry(total=1, connect=None, read=None, redirect=None)) after connection broken by 'ProxyError('Cannot connect to proxy.', timeout('_ssl.c:1106: The handshake operation timed out'))': /bot2070387982:AAFsSEVEQyFjplmKAPgaHOR9F5pa6TZKWz4/getUpdates
2021-11-21 10:00:10,798 - telegram.vendor.ptb_urllib3.urllib3.connectionpool - WARNING - Retrying (Retry(total=0, connect=None, read=None, redirect=None)) after connection broken by 'ProxyError('Cannot connect to proxy.', timeout('_ssl.c:1106: The handshake operation timed out'))': /bot2070387982:AAFsSEVEQyFjplmKAPgaHOR9F5pa6TZKWz4/getUpdates
2021-11-21 10:00:11,533 - telegram.ext.updater - ERROR - Error while getting Updates: urllib3 HTTPError HTTPSConnectionPool(host='api.telegram.org', port=443): Max retries exceeded with url: /bot2070387982:AAFsSEVEQyFjplmKAPgaHOR9F5pa6TZKWz4/getUpdates (Caused by ProxyError('Cannot connect to proxy.', OSError(0, 'Error')))
2021-11-21 10:00:11,552 - codec.tg - ERROR - Exception while handling an update:
Traceback (most recent call last):
  File "/Library/Frameworks/Python.framework/Versions/3.8/lib/python3.8/site-packages/telegram/vendor/ptb_urllib3/urllib3/connectionpool.py", line 611, in urlopen
    self._prepare_proxy(conn)
  File "/Library/Frameworks/Python.framework/Versions/3.8/lib/python3.8/site-packages/telegram/vendor/ptb_urllib3/urllib3/connectionpool.py", line 827, in _prepare_proxy
    conn.connect()
  File "/Library/Frameworks/Python.framework/Versions/3.8/lib/python3.8/site-packages/telegram/vendor/ptb_urllib3/urllib3/connection.py", line 319, in connect
    self.sock = ssl_wrap_socket(
  File "/Library/Frameworks/Python.framework/Versions/3.8/lib/python3.8/site-packages/telegram/vendor/ptb_urllib3/urllib3/util/ssl_.py", line 324, in ssl_wrap_socket
    return context.wrap_socket(sock, server_hostname=server_hostname)
  File "/Library/Frameworks/Python.framework/Versions/3.8/lib/python3.8/ssl.py", line 500, in wrap_socket
    return self.sslsocket_class._create(
  File "/Library/Frameworks/Python.framework/Versions/3.8/lib/python3.8/ssl.py", line 1040, in _create
    self.do_handshake()
  File "/Library/Frameworks/Python.framework/Versions/3.8/lib/python3.8/ssl.py", line 1309, in do_handshake
    self._sslobj.do_handshake()
OSError: [Errno 0] Error

During handling of the above exception, another exception occurred:

Traceback (most recent call last):
  File "/Library/Frameworks/Python.framework/Versions/3.8/lib/python3.8/site-packages/telegram/utils/request.py", line 259, in _request_wrapper
    resp = self._con_pool.request(*args, **kwargs)
  File "/Library/Frameworks/Python.framework/Versions/3.8/lib/python3.8/site-packages/telegram/vendor/ptb_urllib3/urllib3/request.py", line 68, in request
    return self.request_encode_body(method, url, fields=fields,
  File "/Library/Frameworks/Python.framework/Versions/3.8/lib/python3.8/site-packages/telegram/vendor/ptb_urllib3/urllib3/request.py", line 148, in request_encode_body
    return self.urlopen(method, url, **extra_kw)
  File "/Library/Frameworks/Python.framework/Versions/3.8/lib/python3.8/site-packages/telegram/vendor/ptb_urllib3/urllib3/poolmanager.py", line 359, in urlopen
    return super(ProxyManager, self).urlopen(method, url, redirect=redirect, **kw)
  File "/Library/Frameworks/Python.framework/Versions/3.8/lib/python3.8/site-packages/telegram/vendor/ptb_urllib3/urllib3/poolmanager.py", line 244, in urlopen
    response = conn.urlopen(method, u.request_uri, **kw)
  File "/Library/Frameworks/Python.framework/Versions/3.8/lib/python3.8/site-packages/telegram/vendor/ptb_urllib3/urllib3/connectionpool.py", line 691, in urlopen
    return self.urlopen(method, url, body, headers, retries,
  File "/Library/Frameworks/Python.framework/Versions/3.8/lib/python3.8/site-packages/telegram/vendor/ptb_urllib3/urllib3/connectionpool.py", line 691, in urlopen
    return self.urlopen(method, url, body, headers, retries,
  File "/Library/Frameworks/Python.framework/Versions/3.8/lib/python3.8/site-packages/telegram/vendor/ptb_urllib3/urllib3/connectionpool.py", line 691, in urlopen
    return self.urlopen(method, url, body, headers, retries,
  File "/Library/Frameworks/Python.framework/Versions/3.8/lib/python3.8/site-packages/telegram/vendor/ptb_urllib3/urllib3/connectionpool.py", line 665, in urlopen
    retries = retries.increment(method, url, error=e, _pool=self,
  File "/Library/Frameworks/Python.framework/Versions/3.8/lib/python3.8/site-packages/telegram/vendor/ptb_urllib3/urllib3/util/retry.py", line 376, in increment
    raise MaxRetryError(_pool, url, error or ResponseError(cause))
telegram.vendor.ptb_urllib3.urllib3.exceptions.MaxRetryError: HTTPSConnectionPool(host='api.telegram.org', port=443): Max retries exceeded with url: /bot2070387982:AAFsSEVEQyFjplmKAPgaHOR9F5pa6TZKWz4/getUpdates (Caused by ProxyError('Cannot connect to proxy.', OSError(0, 'Error')))

The above exception was the direct cause of the following exception:

Traceback (most recent call last):
  File "/Library/Frameworks/Python.framework/Versions/3.8/lib/python3.8/site-packages/telegram/ext/updater.py", line 646, in _network_loop_retry
    if not action_cb():
  File "/Library/Frameworks/Python.framework/Versions/3.8/lib/python3.8/site-packages/telegram/ext/updater.py", line 597, in polling_action_cb
    updates = self.bot.get_updates(
  File "/Library/Frameworks/Python.framework/Versions/3.8/lib/python3.8/site-packages/telegram/ext/extbot.py", line 222, in get_updates
    updates = super().get_updates(
  File "/Library/Frameworks/Python.framework/Versions/3.8/lib/python3.8/site-packages/telegram/bot.py", line 130, in decorator
    result = func(*args, **kwargs)
  File "/Library/Frameworks/Python.framework/Versions/3.8/lib/python3.8/site-packages/telegram/bot.py", line 2861, in get_updates
    self._post(
  File "/Library/Frameworks/Python.framework/Versions/3.8/lib/python3.8/site-packages/telegram/bot.py", line 295, in _post
    return self.request.post(
  File "/Library/Frameworks/Python.framework/Versions/3.8/lib/python3.8/site-packages/telegram/utils/request.py", line 361, in post
    result = self._request_wrapper(
  File "/Library/Frameworks/Python.framework/Versions/3.8/lib/python3.8/site-packages/telegram/utils/request.py", line 265, in _request_wrapper
    raise NetworkError(f'urllib3 HTTPError {error}') from error
telegram.error.NetworkError: urllib3 HTTPError HTTPSConnectionPool(host='api.telegram.org', port=443): Max retries exceeded with url: /bot2070387982:AAFsSEVEQyFjplmKAPgaHOR9F5pa6TZKWz4/getUpdates (Caused by ProxyError('Cannot connect to proxy.', OSError(0, 'Error')))
2021-11-21 10:00:11,556 - telegram.ext.dispatcher - ERROR - An uncaught error was raised while handling the error.
Traceback (most recent call last):
  File "/Library/Frameworks/Python.framework/Versions/3.8/lib/python3.8/site-packages/telegram/ext/dispatcher.py", line 536, in process_update
    self.dispatch_error(None, update)
  File "/Library/Frameworks/Python.framework/Versions/3.8/lib/python3.8/site-packages/telegram/ext/dispatcher.py", line 810, in dispatch_error
    callback(update, context)
  File "/Users/hesdx/Documents/b95/tgfaucetbot/codec/tg.py", line 107, in error_handler
    else:
NameError: name 'ParseMode' is not defined
2021-11-21 12:16:27,300 - telegram.vendor.ptb_urllib3.urllib3.connectionpool - WARNING - Retrying (Retry(total=2, connect=None, read=None, redirect=None)) after connection broken by 'ProxyError('Cannot connect to proxy.', ConnectionResetError(54, 'Connection reset by peer'))': /bot2070387982:AAFsSEVEQyFjplmKAPgaHOR9F5pa6TZKWz4/getUpdates
2021-11-21 12:16:27,661 - telegram.vendor.ptb_urllib3.urllib3.connectionpool - WARNING - Retrying (Retry(total=1, connect=None, read=None, redirect=None)) after connection broken by 'ProxyError('Cannot connect to proxy.', OSError(0, 'Error'))': /bot2070387982:AAFsSEVEQyFjplmKAPgaHOR9F5pa6TZKWz4/getUpdates
2021-11-21 12:16:27,681 - telegram.vendor.ptb_urllib3.urllib3.connectionpool - WARNING - Retrying (Retry(total=0, connect=None, read=None, redirect=None)) after connection broken by 'ProxyError('Cannot connect to proxy.', OSError(0, 'Error'))': /bot2070387982:AAFsSEVEQyFjplmKAPgaHOR9F5pa6TZKWz4/getUpdates
2021-11-21 12:16:27,698 - telegram.ext.updater - ERROR - Error while getting Updates: urllib3 HTTPError HTTPSConnectionPool(host='api.telegram.org', port=443): Max retries exceeded with url: /bot2070387982:AAFsSEVEQyFjplmKAPgaHOR9F5pa6TZKWz4/getUpdates (Caused by ProxyError('Cannot connect to proxy.', OSError(0, 'Error')))
2021-11-21 12:16:27,700 - codec.tg - ERROR - Exception while handling an update:
Traceback (most recent call last):
  File "/Library/Frameworks/Python.framework/Versions/3.8/lib/python3.8/site-packages/telegram/vendor/ptb_urllib3/urllib3/connectionpool.py", line 611, in urlopen
    self._prepare_proxy(conn)
  File "/Library/Frameworks/Python.framework/Versions/3.8/lib/python3.8/site-packages/telegram/vendor/ptb_urllib3/urllib3/connectionpool.py", line 827, in _prepare_proxy
    conn.connect()
  File "/Library/Frameworks/Python.framework/Versions/3.8/lib/python3.8/site-packages/telegram/vendor/ptb_urllib3/urllib3/connection.py", line 319, in connect
    self.sock = ssl_wrap_socket(
  File "/Library/Frameworks/Python.framework/Versions/3.8/lib/python3.8/site-packages/telegram/vendor/ptb_urllib3/urllib3/util/ssl_.py", line 324, in ssl_wrap_socket
    return context.wrap_socket(sock, server_hostname=server_hostname)
  File "/Library/Frameworks/Python.framework/Versions/3.8/lib/python3.8/ssl.py", line 500, in wrap_socket
    return self.sslsocket_class._create(
  File "/Library/Frameworks/Python.framework/Versions/3.8/lib/python3.8/ssl.py", line 1040, in _create
    self.do_handshake()
  File "/Library/Frameworks/Python.framework/Versions/3.8/lib/python3.8/ssl.py", line 1309, in do_handshake
    self._sslobj.do_handshake()
OSError: [Errno 0] Error

During handling of the above exception, another exception occurred:

Traceback (most recent call last):
  File "/Library/Frameworks/Python.framework/Versions/3.8/lib/python3.8/site-packages/telegram/utils/request.py", line 259, in _request_wrapper
    resp = self._con_pool.request(*args, **kwargs)
  File "/Library/Frameworks/Python.framework/Versions/3.8/lib/python3.8/site-packages/telegram/vendor/ptb_urllib3/urllib3/request.py", line 68, in request
    return self.request_encode_body(method, url, fields=fields,
  File "/Library/Frameworks/Python.framework/Versions/3.8/lib/python3.8/site-packages/telegram/vendor/ptb_urllib3/urllib3/request.py", line 148, in request_encode_body
    return self.urlopen(method, url, **extra_kw)
  File "/Library/Frameworks/Python.framework/Versions/3.8/lib/python3.8/site-packages/telegram/vendor/ptb_urllib3/urllib3/poolmanager.py", line 359, in urlopen
    return super(ProxyManager, self).urlopen(method, url, redirect=redirect, **kw)
  File "/Library/Frameworks/Python.framework/Versions/3.8/lib/python3.8/site-packages/telegram/vendor/ptb_urllib3/urllib3/poolmanager.py", line 244, in urlopen
    response = conn.urlopen(method, u.request_uri, **kw)
  File "/Library/Frameworks/Python.framework/Versions/3.8/lib/python3.8/site-packages/telegram/vendor/ptb_urllib3/urllib3/connectionpool.py", line 691, in urlopen
    return self.urlopen(method, url, body, headers, retries,
  File "/Library/Frameworks/Python.framework/Versions/3.8/lib/python3.8/site-packages/telegram/vendor/ptb_urllib3/urllib3/connectionpool.py", line 691, in urlopen
    return self.urlopen(method, url, body, headers, retries,
  File "/Library/Frameworks/Python.framework/Versions/3.8/lib/python3.8/site-packages/telegram/vendor/ptb_urllib3/urllib3/connectionpool.py", line 691, in urlopen
    return self.urlopen(method, url, body, headers, retries,
  File "/Library/Frameworks/Python.framework/Versions/3.8/lib/python3.8/site-packages/telegram/vendor/ptb_urllib3/urllib3/connectionpool.py", line 665, in urlopen
    retries = retries.increment(method, url, error=e, _pool=self,
  File "/Library/Frameworks/Python.framework/Versions/3.8/lib/python3.8/site-packages/telegram/vendor/ptb_urllib3/urllib3/util/retry.py", line 376, in increment
    raise MaxRetryError(_pool, url, error or ResponseError(cause))
telegram.vendor.ptb_urllib3.urllib3.exceptions.MaxRetryError: HTTPSConnectionPool(host='api.telegram.org', port=443): Max retries exceeded with url: /bot2070387982:AAFsSEVEQyFjplmKAPgaHOR9F5pa6TZKWz4/getUpdates (Caused by ProxyError('Cannot connect to proxy.', OSError(0, 'Error')))

The above exception was the direct cause of the following exception:

Traceback (most recent call last):
  File "/Library/Frameworks/Python.framework/Versions/3.8/lib/python3.8/site-packages/telegram/ext/updater.py", line 646, in _network_loop_retry
    if not action_cb():
  File "/Library/Frameworks/Python.framework/Versions/3.8/lib/python3.8/site-packages/telegram/ext/updater.py", line 597, in polling_action_cb
    updates = self.bot.get_updates(
  File "/Library/Frameworks/Python.framework/Versions/3.8/lib/python3.8/site-packages/telegram/ext/extbot.py", line 222, in get_updates
    updates = super().get_updates(
  File "/Library/Frameworks/Python.framework/Versions/3.8/lib/python3.8/site-packages/telegram/bot.py", line 130, in decorator
    result = func(*args, **kwargs)
  File "/Library/Frameworks/Python.framework/Versions/3.8/lib/python3.8/site-packages/telegram/bot.py", line 2861, in get_updates
    self._post(
  File "/Library/Frameworks/Python.framework/Versions/3.8/lib/python3.8/site-packages/telegram/bot.py", line 295, in _post
    return self.request.post(
  File "/Library/Frameworks/Python.framework/Versions/3.8/lib/python3.8/site-packages/telegram/utils/request.py", line 361, in post
    result = self._request_wrapper(
  File "/Library/Frameworks/Python.framework/Versions/3.8/lib/python3.8/site-packages/telegram/utils/request.py", line 265, in _request_wrapper
    raise NetworkError(f'urllib3 HTTPError {error}') from error
telegram.error.NetworkError: urllib3 HTTPError HTTPSConnectionPool(host='api.telegram.org', port=443): Max retries exceeded with url: /bot2070387982:AAFsSEVEQyFjplmKAPgaHOR9F5pa6TZKWz4/getUpdates (Caused by ProxyError('Cannot connect to proxy.', OSError(0, 'Error')))
2021-11-21 12:16:27,702 - telegram.ext.dispatcher - ERROR - An uncaught error was raised while handling the error.
Traceback (most recent call last):
  File "/Library/Frameworks/Python.framework/Versions/3.8/lib/python3.8/site-packages/telegram/ext/dispatcher.py", line 536, in process_update
    self.dispatch_error(None, update)
  File "/Library/Frameworks/Python.framework/Versions/3.8/lib/python3.8/site-packages/telegram/ext/dispatcher.py", line 810, in dispatch_error
    callback(update, context)
  File "/Users/hesdx/Documents/b95/tgfaucetbot/codec/tg.py", line 107, in error_handler
    else:
NameError: name 'ParseMode' is not defined
